<?xml version='1.0'?>

<robot name="table_bot" xmlns:xacro="http://www.ros.org/wiki/xacro">

  <xacro:include filename="$(find udacity_bot)/urdf/table_bot.gazebo" />
  <link name="robot_footprint"></link>

  <joint name="robot_footprint_joint" type="fixed">
    <origin xyz="0 0 0" rpy="0 0 0" />
    <parent link="robot_footprint"/>
    <child link="base" />
  </joint>

  <link name='base'>
    <!-- <pose>0 0 0.1 0 0 0</pose> -->

    <inertial>
      <mass value="15.0"/>
      <origin xyz="0.0 0 0" rpy=" 0 0 0"/>
      <inertia
          ixx="0.1" ixy="0" ixz="0"
          iyy="0.1" iyz="0"
          izz="0.1"
      />
    </inertial>

    <collision>
      <origin xyz="0 0 0" rpy=" 0 0 0"/> 
      <geometry>
        <box size="0.5 0.3 0.15"/>
      </geometry>
    </collision>

    <visual>
      <origin xyz="0 0 0" rpy=" 0 0 0"/>
      <geometry>
        <box size="0.5 0.3 0.15"/>
      </geometry>
      <material name="Orange">
        <color rgba="1.0 0.5088 0.0468 1.0"/>
      </material>
    </visual>

    <collision>
      <origin xyz="-0.19 0 -0.075" rpy=" 0 0 0"/>
      <geometry>
        <sphere radius="0.059"/>
      </geometry>
      <surface>
        <friction>
          <ode>
            <mu>0</mu>
            <mu2>0</mu2>
            <slip1>1.0</slip1>
            <slip2>1.0</slip2>
          </ode>
        </friction>
      </surface>
    </collision>

    <visual>
      <origin xyz="-0.19 0 -0.075" rpy=" 0 0 0"/>
      <geometry>
        <sphere radius="0.06"/>
      </geometry>
      <material name="Grey">
        <color rgba="0.3 0.3 0.3 1.0"/>
      </material>
    </visual>

  <collision>
      <origin xyz="0.19 0 -0.075" rpy=" 0 0 0"/>
      <geometry>
        <sphere radius="0.059"/>
      </geometry>
      <surface>
        <friction>
          <ode>
            <mu>0</mu>
            <mu2>0</mu2>
            <slip1>1.0</slip1>
            <slip2>1.0</slip2>
          </ode>
        </friction>
      </surface>
    </collision>

    <visual>
      <origin xyz="0.19 0 -0.075" rpy=" 0 0 0"/>
      <geometry>
        <sphere radius="0.06"/>
      </geometry>
      <material name="Grey">
        <color rgba="0.3 0.3 0.3 1.0"/>
      </material>
    </visual>

  </link>

  <link name='top_plate'>
    <inertial>
      <mass value="5.0"/>
      <origin xyz="0.0 0 0" rpy=" 0 0 0"/>
      <inertia
          ixx="0.1" ixy="0" ixz="0"
          iyy="0.1" iyz="0"
          izz="0.1"
      />
    </inertial>

    <collision>
      <origin xyz="0 0 0" rpy=" 0 0 0"/> 
      <geometry>
        <box size="0.5 0.5 0.05"/>
      </geometry>
    </collision>

    <visual>
      <origin xyz="0 0 0" rpy=" 0 0 0"/>
      <geometry>
        <box size="0.5 0.5 0.05"/>
      </geometry>
      <material name="Orange">
        <color rgba="1.0 0.5088 0.0468 1.0"/>
      </material>
    </visual>

  </link>

  <joint name="top_plate_joint" type="fixed">
    <origin xyz="0 0 0.1" rpy="0 0 0" />
    <parent link="base"/>
    <child link="top_plate" />
  </joint>

  <link name='mount'>
    <inertial>
      <mass value="1.0"/>
      <origin xyz="0.0 0 0" rpy=" 0 0 0"/>
      <inertia
          ixx="0.1" ixy="0" ixz="0"
          iyy="0.1" iyz="0"
          izz="0.1"
      />
    </inertial>

    <collision>
      <origin xyz="0 0 0" rpy=" 0 0 0"/> 
      <geometry>
        <box size="0.05 0.05 0.05"/>
      </geometry>
    </collision>

    <visual>
      <origin xyz="0 0 0" rpy=" 0 0 0"/>
      <geometry>
        <box size="0.05 0.05 0.05"/>
      </geometry>
      <material name="Orange">
        <color rgba="1.0 0.5088 0.0468 1.0"/>
      </material>
    </visual>

  </link>

  <joint name="mount_joint" type="fixed">
    <origin xyz="0.275 0 0.025" rpy="0 0 0" />
    <parent link="base"/>
    <child link="mount" />
  </joint>

  <link name='left_wheel'>
    <inertial>
      <mass value="5.0"/>
      <origin xyz="0.0 0 0" rpy=" 0 1.5707 1.5707"/>
      <inertia
          ixx="0.1" ixy="0" ixz="0"
          iyy="0.1" iyz="0"
          izz="0.1"
      />
    </inertial>

    <collision>
      <origin xyz="0 0 0" rpy=" 0 1.5707 1.5707"/>
      <geometry>
        <cylinder length="0.05" radius="0.1"/>
      </geometry>
    </collision>

    <visual>
      <origin xyz="0 0 0" rpy=" 0 1.5707 1.5707"/>
      <geometry>
        <cylinder length="0.05" radius="0.1"/>
      </geometry>
      <material name="Black">
        <color rgba="0 0 0 1.0"/>
      </material>
    </visual>

  </link>

  <joint type="continuous" name="left_wheel_hinge">
    <origin xyz="0.0 0.2 -0.035" rpy="0 0 0"/>
    <child link="left_wheel"/>
    <parent link="base"/>
    <axis xyz="0 1 0" rpy="0 0 0"/>
    <limit effort="10000" velocity="1000"/>
    <joint_properties damping="1.0" friction="1.0"/>
  </joint>

  <link name='right_wheel'>
    <inertial>
      <mass value="5.0"/>
      <origin xyz="0.0 0 0" rpy=" 0 1.5707 1.5707"/>
      <inertia
          ixx="0.1" ixy="0" ixz="0"
          iyy="0.1" iyz="0"
          izz="0.1"
      />
    </inertial>

    <collision>
      <origin xyz="0 0 0" rpy=" 0 1.5707 1.5707"/>
      <geometry>
        <cylinder length="0.05" radius="0.1"/>
      </geometry>
    </collision>

    <visual>
      <origin xyz="0 0 0" rpy=" 0 1.5707 1.5707"/>
      <geometry>
        <cylinder length="0.05" radius="0.1"/>
      </geometry>
      <material name="Black">
        <color rgba="0 0 0 1.0"/>
      </material>
    </visual>

  </link>
    
  <joint type="continuous" name="right_wheel_hinge">
    <origin xyz="0.0 -0.2 -0.035" rpy="0 0 0"/>
    <child link="right_wheel"/>
    <parent link="base"/>
    <axis xyz="0 1 0" rpy="0 0 0"/>
    <limit effort="10000" velocity="1000"/>
    <joint_properties damping="1.0" friction="1.0"/>
  </joint>

  <link name='camera'>
    <inertial>
      <mass value="0.1"/>
      <origin xyz="0 0 0" rpy=" 0 0 0"/>
      <inertia
          ixx="1e-6" ixy="0" ixz="0"
          iyy="1e-6" iyz="0"
          izz="1e-6"
      />
    </inertial>

    <collision>
      <origin xyz="0 0 0" rpy=" 0 0 0"/>
      <geometry>
        <box size="0.025 0.05 0.05"/>
      </geometry>
    </collision>

    <visual>
      <origin xyz="0 0 0" rpy=" 0 0 0"/>
      <geometry>
        <box size="0.025 0.05 0.05"/>
      </geometry>
      <material name="Green">
        <color rgba="0 1.0 0 1.0"/>
      </material>
    </visual>

  </link>

  <joint type="fixed" name="camera_joint">
    <origin xyz="0.0375 0 0" rpy="0 0 0"/>
    <child link="camera"/>
    <parent link="mount"/>
  </joint>

  <link name='hokuyo'>
    <inertial>
      <mass value="0.1"/>
      <origin xyz="0 0 0" rpy=" 0 0 0"/>
      <inertia
          ixx="1e-6" ixy="0" ixz="0"
          iyy="1e-6" iyz="0"
          izz="1e-6"
      />
    </inertial>

    <collision>
      <origin xyz="0 0 0" rpy=" 0 0 0"/>
      <geometry>
        <box size="0.1 0.1 0.1"/>
      </geometry>
    </collision>

    <visual>
      <origin xyz="0 0 0" rpy=" 0 0 0"/>
      <geometry>
        <mesh filename="package://udacity_bot/meshes/hokuyo.dae"/>
      </geometry>
    </visual>

  </link>

  <joint type="fixed" name="hokuyo_joint">
    <origin xyz="0 0 0.05" rpy="0 0 0"/>
    <child link="hokuyo"/>
    <parent link="mount"/>
  </joint>

</robot>
